{"uuid": "26a89790-7111-4a41-a21a-4562d47fb86e", "children": ["3edb0fb4-08db-437a-8139-ffeec529b8b0"], "befores": [{"name": "appium_driver", "status": "broken", "statusDetails": {"message": "urllib3.exceptions.MaxRetryError: HTTPConnectionPool(host='127.0.0.1', port=4723): Max retries exceeded with url: /wd/hub/session (Caused by NewConnectionError('<urllib3.connection.HTTPConnection object at 0x000001E510CB4040>: Failed to establish a new connection: [WinError 10061] No connection could be made because the target machine actively refused it'))\n", "trace": "  File \"C:\\Users\\dines\\AppiumPageObjectModel\\venv\\lib\\site-packages\\pluggy\\_callers.py\", line 39, in _multicall\n    res = hook_impl.function(*args)\n  File \"C:\\Users\\dines\\AppiumPageObjectModel\\venv\\lib\\site-packages\\_pytest\\fixtures.py\", line 1111, in pytest_fixture_setup\n    result = call_fixture_func(fixturefunc, request, kwargs)\n  File \"C:\\Users\\dines\\AppiumPageObjectModel\\venv\\lib\\site-packages\\_pytest\\fixtures.py\", line 883, in call_fixture_func\n    fixture_result = next(generator)\n  File \"C:\\Users\\dines\\AppiumPageObjectModel\\TestCases\\conftest.py\", line 23, in appium_driver\n    driver = webdriver.Remote(\"127.0.0.1:4723/wd/hub\", desire_cap)\n  File \"C:\\Users\\dines\\AppData\\Local\\Programs\\Python\\Python310\\lib\\appium\\webdriver\\webdriver.py\", line 230, in __init__\n    super().__init__(\n  File \"C:\\Users\\dines\\AppiumPageObjectModel\\venv\\lib\\site-packages\\selenium\\webdriver\\remote\\webdriver.py\", line 277, in __init__\n    self.start_session(capabilities, browser_profile)\n  File \"C:\\Users\\dines\\AppData\\Local\\Programs\\Python\\Python310\\lib\\appium\\webdriver\\webdriver.py\", line 320, in start_session\n    response = self.execute(RemoteCommand.NEW_SESSION, w3c_caps)\n  File \"C:\\Users\\dines\\AppiumPageObjectModel\\venv\\lib\\site-packages\\selenium\\webdriver\\remote\\webdriver.py\", line 433, in execute\n    response = self.command_executor.execute(driver_command, params)\n  File \"C:\\Users\\dines\\AppiumPageObjectModel\\venv\\lib\\site-packages\\selenium\\webdriver\\remote\\remote_connection.py\", line 344, in execute\n    return self._request(command_info[0], url, body=data)\n  File \"C:\\Users\\dines\\AppiumPageObjectModel\\venv\\lib\\site-packages\\selenium\\webdriver\\remote\\remote_connection.py\", line 366, in _request\n    response = self._conn.request(method, url, body=body, headers=headers)\n  File \"C:\\Users\\dines\\AppiumPageObjectModel\\venv\\lib\\site-packages\\urllib3\\request.py\", line 78, in request\n    return self.request_encode_body(\n  File \"C:\\Users\\dines\\AppiumPageObjectModel\\venv\\lib\\site-packages\\urllib3\\request.py\", line 170, in request_encode_body\n    return self.urlopen(method, url, **extra_kw)\n  File \"C:\\Users\\dines\\AppiumPageObjectModel\\venv\\lib\\site-packages\\urllib3\\poolmanager.py\", line 376, in urlopen\n    response = conn.urlopen(method, u.request_uri, **kw)\n  File \"C:\\Users\\dines\\AppiumPageObjectModel\\venv\\lib\\site-packages\\urllib3\\connectionpool.py\", line 815, in urlopen\n    return self.urlopen(\n  File \"C:\\Users\\dines\\AppiumPageObjectModel\\venv\\lib\\site-packages\\urllib3\\connectionpool.py\", line 815, in urlopen\n    return self.urlopen(\n  File \"C:\\Users\\dines\\AppiumPageObjectModel\\venv\\lib\\site-packages\\urllib3\\connectionpool.py\", line 815, in urlopen\n    return self.urlopen(\n  File \"C:\\Users\\dines\\AppiumPageObjectModel\\venv\\lib\\site-packages\\urllib3\\connectionpool.py\", line 787, in urlopen\n    retries = retries.increment(\n  File \"C:\\Users\\dines\\AppiumPageObjectModel\\venv\\lib\\site-packages\\urllib3\\util\\retry.py\", line 592, in increment\n    raise MaxRetryError(_pool, url, error or ResponseError(cause))\n"}, "start": 1659338024202, "stop": 1659338032384}], "start": 1659338024202, "stop": 1659338032502}